{"Q_ID": "1220110014", "S_NAME": "Exceptional & File Handli", "Q_NAME": "Debug the program", "Q_DESC": "Debug the program and get the desired output:\n\n#include<iostream>\n#include<cmath>\nusing namespace std;\nint main(void)\n{\n cout << \"Start\" << endl;\n try {\nint a;\n cout << \"Inside try block.\" << endl;\ncin >>a;\n throw a;\n cout << \"This will not execute.\";\n }\n catch(int i) {\n cout << \"Caught an exception=value is: \";\n cout << i << endl;\n }\n cout << \"End\";\n return 0;\n}", "TESTCASE_1": "23\n###---###SEPERATOR---###---\nStart\nInside try block.\nCaught an exception value is=23\nEnd", "TESTCASE_2": "99\n###---###SEPERATOR---###---\nStart\nInside try block.\nCaught an exception value is=99\nEnd", "TESTCASE_3": "0\n###---###SEPERATOR---###---\n0", "TESTCASE_4": "0\n###---###SEPERATOR---###---\n0", "TESTCASE_5": "0\n###---###SEPERATOR---###---\n0"}